<?xml version="1.0"?>
<robot name="jetbot">
  <!-- ................................... -->
  <!-- VERZIA 0.65 Skutočný robot JetBot-->
  <!-- ................................... -->
  <!-- Materiály -->
  <material name="green">
    <color rgba="0 1 0 1"/>
  </material>
  <material name="blue">
    <color rgba="0 0 1 1"/>
  </material>
  <material name="black">
    <color rgba="0 0 0 1"/>
  </material>
  <material name="grey">
    <color rgba="0.7 0.7 0.7 1"/>
  </material>
  <material name="dark_green">
    <color rgba="0.0 0.4 0.0 1"/>
  </material>
  <material name="medium_green">
    <color rgba="0.0 0.6 0.0 1"/>
  </material>
  <material name="dark_grey">
    <color rgba="0.2 0.2 0.2 1"/>
  </material>
  <material name="yellow">
    <color rgba="1 1 0 1"/>
  </material>

  <!-- Root link: base_footprint -->
  <link name="base_footprint">
    <inertial>
      <mass value="0.0001"/>
      <inertia ixx="0.0001" ixy="0" ixz="0" iyy="0.0001" iyz="0" izz="0.0001"/>
    </inertial>
  </link>

  <!-- Telo robota -->
  <link name="base_link">
    <visual>
      <geometry>
        <cylinder radius="0.1066" length="0.05"/>
      </geometry>
      <material name="green"/>
    </visual>
    <collision name="base_link_collision">
      <geometry>
        <cylinder radius="0.1066" length="0.05"/>
      </geometry>
    </collision>
  </link>

  <joint name="base_footprint_to_base_link" type="fixed">
    <parent link="base_footprint"/>
    <child link="base_link"/>
    <origin xyz="0 0 0.033" rpy="0 0 0"/>
  </joint>

  <!-- IMU -->
  <link name="base_imu_link">
    <visual>
      <geometry>
        <box size="0.01 0.01 0.01"/>
      </geometry>
      <material name="grey"/>
    </visual>
    <inertial>
      <mass value="0.01"/>
      <inertia ixx="0.0001" ixy="0" ixz="0" iyy="0.0001" iyz="0" izz="0.0001"/>
    </inertial>
  </link>

  <joint name="imu_joint" type="fixed">
    <parent link="base_link"/>
    <child link="base_imu_link"/>
    <origin xyz="0 0 0.037" rpy="0 0 0"/>
  </joint>

  <!-- Ľavé koleso -->
  <link name="left_wheel">
    <visual>
      <geometry>
        <cylinder radius="0.033" length="0.02"/>
      </geometry>
      <origin xyz="0 0 0" rpy="1.5707 0 0"/>
      <material name="blue"/>
    </visual>
    <collision name="left_wheel_collision">
      <geometry>
        <cylinder radius="0.033" length="0.02"/>
      </geometry>
      <origin xyz="0 0 0" rpy="1.5707 0 0"/>
    </collision>
    <inertial>
      <mass value="0.1"/>
      <origin xyz="0 0 0"/>
      <inertia ixx="0.000036" ixy="0" ixz="0" iyy="0.000054" iyz="0" izz="0.000054"/>
    </inertial>
  </link>

  <joint name="left_wheel_joint" type="continuous">
    <parent link="base_link"/>
    <child link="left_wheel"/>
    <origin xyz="0 0.1066 -0.033"/>
    <axis xyz="0 1 0"/>
    <dynamics damping="0.5" friction="0.1"/>
  </joint>

  <!-- Pravé koleso -->
  <link name="right_wheel">
    <visual>
      <geometry>
        <cylinder radius="0.033" length="0.02"/>
      </geometry>
      <origin xyz="0 0 0" rpy="1.5707 0 0"/>
      <material name="blue"/>
    </visual>
    <collision name="right_wheel_collision">
      <geometry>
        <cylinder radius="0.033" length="0.02"/>
      </geometry>
      <origin xyz="0 0 0" rpy="1.5707 0 0"/>
    </collision>
    <inertial>
      <mass value="0.1"/>
      <origin xyz="0 0 0"/>
      <inertia ixx="0.000036" ixy="0" ixz="0" iyy="0.000054" iyz="0" izz="0.000054"/>
    </inertial>
  </link>

  <joint name="right_wheel_joint" type="continuous">
    <parent link="base_link"/>
    <child link="right_wheel"/>
    <origin xyz="0 -0.1066 -0.033"/>
    <axis xyz="0 1 0"/>
    <dynamics damping="0.5" friction="0.1"/>
  </joint>

  <!-- Podstavec pre pomocné koleso -->
  <link name="balance_wheel_base">
    <visual>
      <geometry>
        <box size="0.02 0.02 0.02"/>
      </geometry>
      <material name="grey"/>
    </visual>
    <collision name="balance_wheel_base_collision">
      <geometry>
        <box size="0.02 0.02 0.02"/>
      </geometry>
    </collision>
    <inertial>
      <mass value="0.01"/>
      <origin xyz="0 0 0"/>
      <inertia ixx="0.0001" ixy="0" ixz="0" iyy="0.0001" iyz="0" izz="0.0001"/>
    </inertial>
  </link>

  <joint name="balance_wheel_base_joint" type="continuous">
    <parent link="base_link"/>
    <child link="balance_wheel_base"/>
    <origin xyz="0.07 0 -0.034" rpy="0 0 0"/>
    <axis xyz="0 0 1"/>
    <dynamics damping="0.1" friction="0.01"/>
  </joint>

  <!-- Pomocné koleso -->
  <link name="balance_wheel">
    <visual>
      <geometry>
        <sphere radius="0.009"/>
      </geometry>
      <material name="black"/>
    </visual>
    <collision name="balance_wheel_collision">
      <geometry>
        <sphere radius="0.009"/>
      </geometry>
    </collision>
    <inertial>
      <mass value="0.05"/>
      <origin xyz="0 0 0"/>
      <inertia ixx="0.0005" ixy="0" ixz="0" iyy="0.0005" iyz="0" izz="0.0005"/>
    </inertial>
  </link>

  <joint name="balance_wheel_joint" type="fixed">
    <parent link="balance_wheel_base"/>
    <child link="balance_wheel"/>
    <origin xyz="0 0 -0.01" rpy="1.5707 0 0"/>
  </joint>

  <!-- Podstavec pre pomocné koleso_2 -->
  <link name="balance_wheel_2_base">
    <visual>
      <geometry>
        <box size="0.02 0.02 0.02"/>
      </geometry>
      <material name="grey"/>
    </visual>
    <collision name="balance_wheel_2_base_collision">
      <geometry>
        <box size="0.02 0.02 0.02"/>
      </geometry>
    </collision>
    <inertial>
      <mass value="0.01"/>
      <origin xyz="0 0 0"/>
      <inertia ixx="0.0001" ixy="0" ixz="0" iyy="0.0001" iyz="0" izz="0.0001"/>
    </inertial>
  </link>

  <joint name="balance_wheel_2_base_joint" type="continuous">
    <parent link="base_link"/>
    <child link="balance_wheel_2_base"/>
    <origin xyz="-0.07 0 -0.034" rpy="0 0 0"/>
    <axis xyz="0 0 1"/>
    <dynamics damping="0.1" friction="0.01"/>
  </joint>

  <!-- Pomocné koleso_2 -->
  <link name="balance_wheel_2">
    <visual>
      <geometry>
        <sphere radius="0.009"/>
      </geometry>
      <material name="black"/>
    </visual>
    <collision name="balance_wheel_2_collision">
      <geometry>
        <sphere radius="0.009"/>
      </geometry>
    </collision>
    <inertial>
      <mass value="0.05"/>
      <origin xyz="0 0 0"/>
      <inertia ixx="0.0005" ixy="0" ixz="0" iyy="0.0005" iyz="0" izz="0.0005"/>
    </inertial>
  </link>

  <joint name="balance_wheel_2_joint" type="fixed">
    <parent link="balance_wheel_2_base"/>
    <child link="balance_wheel_2"/>
    <origin xyz="0 0 -0.01" rpy="1.5707 0 0"/>
  </joint>

  <!-- Anténka_1 -->
  <link name="antenna_1">
    <visual>
      <geometry>
        <cylinder radius="0.005" length="0.15"/>
      </geometry>
      <material name="black"/>
    </visual>
    <collision name="antenna_1_collision">
      <geometry>
        <cylinder radius="0.005" length="0.15"/>
      </geometry>
    </collision>
    <inertial>
      <mass value="0.02"/>
      <origin xyz="0 0 0"/>
      <inertia ixx="0.0002" ixy="0" ixz="0" iyy="0.0002" iyz="0" izz="0.0002"/>
    </inertial>
  </link>

  <joint name="antenna_1_joint" type="fixed">
    <parent link="base_link"/>
    <child link="antenna_1"/>
    <origin xyz="-0.08 0.04 0.09" rpy="0 0 0"/>
  </joint>

  <!-- Anténka_2 -->
  <link name="antenna_2">
    <visual>
      <geometry>
        <cylinder radius="0.005" length="0.15"/>
      </geometry>
      <material name="black"/>
    </visual>
    <collision name="antenna_2_collision">
      <geometry>
        <cylinder radius="0.005" length="0.15"/>
      </geometry>
    </collision>
    <inertial>
      <mass value="0.02"/>
      <origin xyz="0 0 0"/>
      <inertia ixx="0.0002" ixy="0" ixz="0" iyy="0.0002" iyz="0" izz="0.0002"/>
    </inertial>
  </link>

  <joint name="antenna_2_joint" type="fixed">
    <parent link="base_link"/>
    <child link="antenna_2"/>
    <origin xyz="-0.08 -0.04 0.09" rpy="0 0 0"/>
  </joint>

  <!-- Piliere spodné -->
  <link name="pillar_1">
    <visual>
      <geometry>
        <cylinder radius="0.005" length="0.05"/>
      </geometry>
      <material name="black"/>
    </visual>
    <collision name="pillar_1_collision">
      <geometry>
        <cylinder radius="0.005" length="0.05"/>
      </geometry>
    </collision>
    <inertial>
      <mass value="0.05"/>
      <origin xyz="0 0 0"/>
      <inertia ixx="0.0005" ixy="0" ixz="0" iyy="0.0005" iyz="0" izz="0.0005"/>
    </inertial>
  </link>

  <joint name="pillar_1_joint" type="fixed">
    <parent link="base_link"/>
    <child link="pillar_1"/>
    <origin xyz="0.05 0.05 0.025" rpy="0 0 0"/>
  </joint>

  <link name="pillar_2">
    <visual>
      <geometry>
        <cylinder radius="0.005" length="0.05"/>
      </geometry>
      <material name="black"/>
    </visual>
    <collision name="pillar_2_collision">
      <geometry>
        <cylinder radius="0.005" length="0.05"/>
      </geometry>
    </collision>
    <inertial>
      <mass value="0.05"/>
      <origin xyz="0 0 0"/>
      <inertia ixx="0.0005" ixy="0" ixz="0" iyy="0.0005" iyz="0" izz="0.0005"/>
    </inertial>
  </link>

  <joint name="pillar_2_joint" type="fixed">
    <parent link="base_link"/>
    <child link="pillar_2"/>
    <origin xyz="-0.05 0.05 0.025" rpy="0 0 0"/>
  </joint>

  <link name="pillar_3">
    <visual>
      <geometry>
        <cylinder radius="0.005" length="0.05"/>
      </geometry>
      <material name="black"/>
    </visual>
    <collision name="pillar_3_collision">
      <geometry>
        <cylinder radius="0.005" length="0.05"/>
      </geometry>
    </collision>
    <inertial>
      <mass value="0.05"/>
      <origin xyz="0 0 0"/>
      <inertia ixx="0.0005" ixy="0" ixz="0" iyy="0.0005" iyz="0" izz="0.0005"/>
    </inertial>
  </link>

  <joint name="pillar_3_joint" type="fixed">
    <parent link="base_link"/>
    <child link="pillar_3"/>
    <origin xyz="0.05 -0.05 0.025" rpy="0 0 0"/>
  </joint>

  <link name="pillar_4">
    <visual>
      <geometry>
        <cylinder radius="0.005" length="0.05"/>
      </geometry>
      <material name="black"/>
    </visual>
    <collision name="pillar_4_collision">
      <geometry>
        <cylinder radius="0.005" length="0.05"/>
      </geometry>
    </collision>
    <inertial>
      <mass value="0.05"/>
      <origin xyz="0 0 0"/>
      <inertia ixx="0.0005" ixy="0" ixz="0" iyy="0.0005" iyz="0" izz="0.0005"/>
    </inertial>
  </link>

  <joint name="pillar_4_joint" type="fixed">
    <parent link="base_link"/>
    <child link="pillar_4"/>
    <origin xyz="-0.05 -0.05 0.025" rpy="0 0 0"/>
  </joint>

  <!-- Speaker -->
  <link name="speaker">
    <visual>
      <geometry>
        <cylinder radius="0.01" length="0.004"/>
      </geometry>
      <material name="black"/>
    </visual>
    <collision name="speaker_collision">
      <geometry>
        <cylinder radius="0.01" length="0.004"/>
      </geometry>
    </collision>
    <inertial>
      <mass value="0.01"/>
      <origin xyz="0 0 0"/>
      <inertia ixx="0.0001" ixy="0" ixz="0" iyy="0.0001" iyz="0" izz="0.0001"/>
    </inertial>
  </link>

  <joint name="speaker_joint" type="fixed">
    <parent link="base_link"/>
    <child link="speaker"/>
    <origin xyz="-0.05 0.075 0.026" rpy="0 0 0"/>
  </joint>

  <!-- Podstavec -->
  <link name="plate">
    <visual>
      <geometry>
        <box size="0.12 0.12 0.001"/>
      </geometry>
      <material name="dark_green"/>
    </visual>
    <collision name="plate_collision">
      <geometry>
        <box size="0.12 0.12 0.001"/>
      </geometry>
    </collision>
    <inertial>
      <mass value="0.1"/>
      <origin xyz="0 0 0"/>
      <inertia ixx="0.001" ixy="0" ixz="0" iyy="0.001" iyz="0" izz="0.001"/>
    </inertial>
  </link>

  <joint name="plate_joint" type="fixed">
    <parent link="base_link"/>
    <child link="plate"/>
    <origin xyz="0 0 0.050" rpy="0 0 0"/>
  </joint>

  <!-- Matičná doska -->
  <link name="motherboard">
    <visual>
      <geometry>
        <box size="0.08 0.08 0.009"/>
      </geometry>
      <material name="grey"/>
    </visual>
    <collision name="motherboard_collision">
      <geometry>
        <box size="0.08 0.08 0.009"/>
      </geometry>
    </collision>
    <inertial>
      <mass value="0.2"/>
      <origin xyz="0 0 0"/>
      <inertia ixx="0.001" ixy="0" ixz="0" iyy="0.001" iyz="0" izz="0.001"/>
    </inertial>
  </link>

  <joint name="motherboard_joint" type="fixed">
    <parent link="plate"/>
    <child link="motherboard"/>
    <origin xyz="0 0 0.005" rpy="0 0 0"/>
  </joint>

  <!-- Podstavec_2_vrchný -->
  <link name="top_plate">
    <visual>
      <geometry>
        <box size="0.12 0.12 0.005"/>
      </geometry>
      <material name="medium_green"/>
    </visual>
    <collision name="top_plate_collision">
      <geometry>
        <box size="0.12 0.12 0.005"/>
      </geometry>
    </collision>
    <inertial>
      <mass value="0.1"/>
      <origin xyz="0 0 0"/>
      <inertia ixx="0.0005" ixy="0" ixz="0" iyy="0.0005" iyz="0" izz="0.0005"/>
    </inertial>
  </link>

  <joint name="top_plate_joint" type="fixed">
    <parent link="plate"/>
    <child link="top_plate"/>
    <origin xyz="0 0 0.025" rpy="0 0 0"/>
  </joint>

  <!-- Jetson Nano počítač -->
  <link name="jetson_nano">
    <visual>
      <geometry>
        <box size="0.08 0.08 0.014"/>
      </geometry>
      <material name="dark_grey"/>
    </visual>
    <collision name="jetson_nano_collision">
      <geometry>
        <box size="0.08 0.08 0.014"/>
      </geometry>
    </collision>
    <inertial>
      <mass value="0.2"/>
      <origin xyz="0 0 0"/>
      <inertia ixx="0.001" ixy="0" ixz="0" iyy="0.001" iyz="0" izz="0.001"/>
    </inertial>
  </link>

  <joint name="jetson_nano_joint" type="fixed">
    <parent link="top_plate"/>
    <child link="jetson_nano"/>
    <origin xyz="0 0 -0.005" rpy="0 0 0"/>
  </joint>

  <!-- Piliere vrchné -->
  <link name="pillar_5">
    <visual>
      <geometry>
        <cylinder radius="0.005" length="0.025"/>
      </geometry>
      <material name="black"/>
    </visual>
    <collision name="pillar_5_collision">
      <geometry>
        <cylinder radius="0.005" length="0.025"/>
      </geometry>
    </collision>
    <inertial>
      <mass value="0.02"/>
      <origin xyz="0 0 0"/>
      <inertia ixx="0.0002" ixy="0" ixz="0" iyy="0.0002" iyz="0" izz="0.0002"/>
    </inertial>
  </link>

  <joint name="pillar_5_joint" type="fixed">
    <parent link="plate"/>
    <child link="pillar_5"/>
    <origin xyz="0.045 0.045 0.0125" rpy="0 0 0"/>
  </joint>

  <link name="pillar_6">
    <visual>
      <geometry>
        <cylinder radius="0.005" length="0.025"/>
      </geometry>
      <material name="black"/>
    </visual>
    <collision name="pillar_6_collision">
      <geometry>
        <cylinder radius="0.005" length="0.025"/>
      </geometry>
    </collision>
    <inertial>
      <mass value="0.02"/>
      <origin xyz="0 0 0"/>
      <inertia ixx="0.0002" ixy="0" ixz="0" iyy="0.0002" iyz="0" izz="0.0002"/>
    </inertial>
  </link>

  <joint name="pillar_6_joint" type="fixed">
    <parent link="plate"/>
    <child link="pillar_6"/>
    <origin xyz="-0.045 0.045 0.0125" rpy="0 0 0"/>
  </joint>

  <link name="pillar_7">
    <visual>
      <geometry>
        <cylinder radius="0.005" length="0.025"/>
      </geometry>
      <material name="black"/>
    </visual>
    <collision name="pillar_7_collision">
      <geometry>
        <cylinder radius="0.005" length="0.025"/>
      </geometry>
    </collision>
    <inertial>
      <mass value="0.02"/>
      <origin xyz="0 0 0"/>
      <inertia ixx="0.0002" ixy="0" ixz="0" iyy="0.0002" iyz="0" izz="0.0002"/>
    </inertial>
  </link>

  <joint name="pillar_7_joint" type="fixed">
    <parent link="plate"/>
    <child link="pillar_7"/>
    <origin xyz="0.045 -0.045 0.0125" rpy="0 0 0"/>
  </joint>

  <link name="pillar_8">
    <visual>
      <geometry>
        <cylinder radius="0.005" length="0.025"/>
      </geometry>
      <material name="black"/>
    </visual>
    <collision name="pillar_8_collision">
      <geometry>
        <cylinder radius="0.005" length="0.025"/>
      </geometry>
    </collision>
    <inertial>
      <mass value="0.02"/>
      <origin xyz="0 0 0"/>
      <inertia ixx="0.0002" ixy="0" ixz="0" iyy="0.0002" iyz="0" izz="0.0002"/>
    </inertial>
  </link>

  <joint name="pillar_8_joint" type="fixed">
    <parent link="plate"/>
    <child link="pillar_8"/>
    <origin xyz="-0.045 -0.045 0.0125" rpy="0 0 0"/>
  </joint>

  <!-- Batérie -->
  <link name="battery_1">
    <visual>
      <geometry>
        <cylinder radius="0.009" length="0.050"/>
      </geometry>
      <material name="yellow"/>
    </visual>
    <collision name="battery_1_collision">
      <geometry>
        <cylinder radius="0.009" length="0.050"/>
      </geometry>
    </collision>
    <inertial>
      <mass value="0.05"/>
      <origin xyz="0 0 0"/>
      <inertia ixx="0.0005" ixy="0" ixz="0" iyy="0.0005" iyz="0" izz="0.0005"/>
    </inertial>
  </link>

  <joint name="battery_1_joint" type="fixed">
    <parent link="plate"/>
    <child link="battery_1"/>
    <origin xyz="-0.018 0 -0.010" rpy="1.5707 1.5707 0"/>
  </joint>

  <link name="battery_2">
    <visual>
      <geometry>
        <cylinder radius="0.009" length="0.050"/>
      </geometry>
      <material name="yellow"/>
    </visual>
    <collision name="battery_2_collision">
      <geometry>
        <cylinder radius="0.009" length="0.050"/>
      </geometry>
    </collision>
    <inertial>
      <mass value="0.05"/>
      <origin xyz="0 0 0"/>
      <inertia ixx="0.0005" ixy="0" ixz="0" iyy="0.0005" iyz="0" izz="0.0005"/>
    </inertial>
  </link>

  <joint name="battery_2_joint" type="fixed">
    <parent link="plate"/>
    <child link="battery_2"/>
    <origin xyz="0 0 -0.010" rpy="1.5707 1.5707 0"/>
  </joint>

  <link name="battery_3">
    <visual>
      <geometry>
        <cylinder radius="0.009" length="0.050"/>
      </geometry>
      <material name="yellow"/>
    </visual>
    <collision name="battery_3_collision">
      <geometry>
        <cylinder radius="0.009" length="0.050"/>
      </geometry>
    </collision>
    <inertial>
      <mass value="0.05"/>
      <origin xyz="0 0 0"/>
      <inertia ixx="0.0005" ixy="0" ixz="0" iyy="0.0005" iyz="0" izz="0.0005"/>
    </inertial>
  </link>

  <joint name="battery_3_joint" type="fixed">
    <parent link="plate"/>
    <child link="battery_3"/>
    <origin xyz="0.018 0 -0.010" rpy="1.5707 1.5707 0"/>
  </joint>

  <!-- Podstavec pre kameru -->
  <link name="camera_base">
    <visual>
      <geometry>
        <box size="0.015 0.010 0.04"/>
      </geometry>
      <material name="green"/>
    </visual>
    <collision name="camera_base_collision">
      <geometry>
        <box size="0.015 0.010 0.04"/>
      </geometry>
    </collision>
    <inertial>
      <mass value="0.05"/>
      <origin xyz="0 0 0"/>
      <inertia ixx="0.0005" ixy="0" ixz="0" iyy="0.0005" iyz="0" izz="0.0005"/>
    </inertial>
  </link>

  <joint name="camera_base_joint" type="fixed">
    <parent link="base_link"/>
    <child link="camera_base"/>
    <origin xyz="0.09 0 0.037" rpy="0 0 0"/>
  </joint>

  <!-- Kamera -->
  <link name="csi_cam_0_link">
    <visual>
      <geometry>
        <box size="0.02 0.02 0.02"/>
      </geometry>
      <material name="black"/>
    </visual>
    <collision name="csi_cam_0_link_collision">
      <geometry>
        <box size="0.02 0.02 0.02"/>
      </geometry>
    </collision>
    <inertial>
      <mass value="0.05"/>
      <origin xyz="0 0 0"/>
      <inertia ixx="0.0001" ixy="0" ixz="0" iyy="0.0001" iyz="0" izz="0.0001"/>
    </inertial>
  </link>
  <joint name="camera_joint" type="fixed">
    <parent link="camera_base"/>
    <child link="csi_cam_0_link"/>
    <origin xyz="0.01 0 0.02361" rpy="0 0.15 0"/>
  </joint>

  <!-- Podstavec pre LIDAR -->
  <link name="lidar_base">
    <visual>
      <geometry>
        <cylinder radius="0.04" length="0.030"/>
      </geometry>
      <material name="green"/>
    </visual>
    <collision name="lidar_base_collision">
      <geometry>
        <cylinder radius="0.04" length="0.030"/>
      </geometry>
    </collision>
    <inertial>
      <mass value="0.1"/>
      <origin xyz="0 0 0"/>
      <inertia ixx="0.001" ixy="0" ixz="0" iyy="0.001" iyz="0" izz="0.002"/>
    </inertial>
  </link>

  <joint name="lidar_base_joint" type="fixed">
    <parent link="top_plate"/>
    <child link="lidar_base"/>
    <origin xyz="0 0 0.042" rpy="3.14 0 0"/>
  </joint>

  <!-- LIDAR -->
  <link name="laser_frame">
    <visual>
      <geometry>
        <cylinder radius="0.04" length="0.02"/>
      </geometry>
      <material name="black"/>
    </visual>
    <collision name="laser_frame_collision">
      <geometry>
        <cylinder radius="0.04" length="0.02"/>
      </geometry>
    </collision>
    <inertial>
      <mass value="0.1"/>
      <origin xyz="0 0 0"/>
      <inertia ixx="0.001" ixy="0" ixz="0" iyy="0.001" iyz="0" izz="0.002"/>
    </inertial>
  </link>

  <joint name="lidar_joint" type="fixed">
    <parent link="lidar_base"/>
    <child link="laser_frame"/>
    <origin xyz="0 0 0" rpy="0 0 0"/>
  </joint>
</robot>
