<?xml version="1.0"?>
<robot name="jetbot">
  <!-- ................................... -->
  <!-- VERZIA 0.63 -->
  <!-- ................................... -->
  <!-- Materiály -->
  <material name="green">
    <color rgba="0 1 0 1"/>
  </material>
  <material name="blue">
    <color rgba="0 0 1 1"/>
  </material>
  <material name="black">
    <color rgba="0 0 0 1"/>
  </material>
  <material name="grey">
    <color rgba="0.7 0.7 0.7 1"/>
  </material>
  <material name="dark_green">
    <color rgba="0.0 0.4 0.0 1"/>
  </material>
  <material name="medium_green">
    <color rgba="0.0 0.6 0.0 1"/>
  </material>
  <material name="dark_grey">
    <color rgba="0.2 0.2 0.2 1"/>
  </material>
  <material name="yellow">
    <color rgba="1 1 0 1"/>
  </material>

  <!-- Telo robota -->
  <link name="base_link">
    <visual>
      <geometry>
        <cylinder radius="0.1066" length="0.05"/> <!-- Upravený radius 0.1 -->
      </geometry>
      <material name="green"/>
    </visual>
    <collision name="base_link_collision">
      <geometry>
        <cylinder radius="0.1066" length="0.05"/> <!-- Upravený radius 0.1 -->
      </geometry>
    </collision>
    <inertial>
      <mass value="1.6"/>
      <origin xyz="0 0 0"/>
      <inertia ixx="0.0055" ixy="0" ixz="0" iyy="0.0055" iyz="0" izz="0.0091"/>
    </inertial>
    
    <!-- Sensor pre IMU -->
    <sensor type="imu" name="imu_sensor">
      <update_rate>100</update_rate>
      <always_on>1</always_on>
      <visualize>true</visualize>
      <topic>/imu</topic>
    </sensor>
    
    <!-- Sensor pre kontaktný senzor -->
    <sensor type="contact" name="contact_sensor">
      <update_rate>100</update_rate>
      <contact>
        <collision>base_link_collision</collision>
        <collision>left_wheel_collision</collision>
        <collision>right_wheel_collision</collision>
      </contact>
    </sensor>
  </link>
  
  <gazebo reference="base_link">
    <material>Gazebo/Green</material>
    <mu1>0.5</mu1>
    <mu2>0.5</mu2>
  </gazebo>
    
  <!-- Ľavé koleso -->
  <link name="left_wheel">
    <visual>
      <geometry>
        <cylinder radius="0.033" length="0.02"/> <!-- Upravený radius 0.03 -->
      </geometry>
      <origin xyz="0 0 0" rpy="1.5707 0 0"/>
      <material name="blue"/>
    </visual>
    <collision name="left_wheel_collision">
      <geometry>
        <cylinder radius="0.033" length="0.02"/> <!-- Upravený radius 0.03 -->
      </geometry>
      <origin xyz="0 0 0" rpy="1.5707 0 0"/>
    </collision>
    <inertial>
      <mass value="0.1"/>
      <origin xyz="0 0 0"/>
      <inertia ixx="0.000036" ixy="0" ixz="0" iyy="0.000054" iyz="0" izz="0.000054"/>
    </inertial>
  </link>
  <gazebo reference="left_wheel">
    <material>Gazebo/Blue</material>
    <mu1>2.0</mu1>
    <mu2>2.0</mu2>
  </gazebo>

  <joint name="left_wheel_joint" type="continuous">
    <parent link="base_link"/>
    <child link="left_wheel"/>
    <origin xyz="0 0.1066 -0.02" rpy="0 0 0"/> <!-- Upravený origin 0.11 -->
    <axis xyz="0 1 0"/>
    <dynamics damping="0.5" friction="0.1"/>
  </joint>

  <!-- Pravé koleso -->
  <link name="right_wheel">
    <visual>
      <geometry>
        <cylinder radius="0.033" length="0.02"/> <!-- Upravený radius 0.03 -->
      </geometry>
      <origin xyz="0 0 0" rpy="1.5707 0 0"/>
      <material name="blue"/>
    </visual>
    <collision name="right_wheel_collision">
      <geometry>
        <cylinder radius="0.033" length="0.02"/> <!-- Upravený radius 0.03 -->
      </geometry>
      <origin xyz="0 0 0" rpy="1.5707 0 0"/>
    </collision>
    <inertial>
      <mass value="0.1"/>
      <origin xyz="0 0 0"/>
      <inertia ixx="0.000036" ixy="0" ixz="0" iyy="0.000054" iyz="0" izz="0.000054"/>
    </inertial>
  </link>
  <gazebo reference="right_wheel">
    <material>Gazebo/Blue</material>
    <mu1>2.0</mu1>
    <mu2>2.0</mu2>
  </gazebo>

  <joint name="right_wheel_joint" type="continuous">
    <parent link="base_link"/>
    <child link="right_wheel"/>
    <origin xyz="0 -0.1066 -0.02" rpy="0 0 0"/> <!-- Upravený origin -0.11 -->
    <axis xyz="0 1 0"/>
    <dynamics damping="0.5" friction="0.1"/>
  </joint>

  <!-- Podstavec pre pomocné koleso -->
  <link name="balance_wheel_base">
    <visual>
      <geometry>
        <box size="0.02 0.02 0.02"/>
      </geometry>
      <material name="grey"/>
    </visual>
    <collision name="balance_wheel_base_collision">
      <geometry>
        <box size="0.02 0.02 0.02"/>
      </geometry>
    </collision>
    <inertial>
      <mass value="0.01"/>
      <origin xyz="0 0 0"/>
      <inertia ixx="0.0001" ixy="0" ixz="0" iyy="0.0001" iyz="0" izz="0.0001"/>
    </inertial>
  </link>
  <gazebo reference="balance_wheel_base">
    <material>Gazebo/Grey</material>
  </gazebo>
  <joint name="balance_wheel_base_joint" type="continuous">
    <parent link="base_link"/>
    <child link="balance_wheel_base"/>
    <origin xyz="0.07 0 -0.034" rpy="0 0 0"/>
    <axis xyz="0 0 1"/>
    <dynamics damping="0.1" friction="0.01"/>
  </joint>

  <!-- Pomocné koleso -->
  <link name="balance_wheel">
    <visual>
      <geometry>
        <sphere radius="0.009"/>
      </geometry>
      <material name="black"/>
    </visual>
    <collision name="balance_wheel_collision">
      <geometry>
        <sphere radius="0.009"/>
      </geometry>
    </collision>
    <inertial>
      <mass value="0.05"/>
      <origin xyz="0 0 0"/>
      <inertia ixx="0.0005" ixy="0" ixz="0" iyy="0.0005" iyz="0" izz="0.0005"/>
    </inertial>
  </link>
  <gazebo reference="balance_wheel">
    <material>Gazebo/Black</material>
    <mu1>0.1</mu1>
    <mu2>0.1</mu2>
  </gazebo>
  <joint name="balance_wheel_joint" type="fixed">
    <parent link="balance_wheel_base"/>
    <child link="balance_wheel"/>
    <origin xyz="0 0 -0.01" rpy="1.5707 0 0"/> <!-- Úprava origin 0.1 -->
  </joint>

  <!-- Podstavec pre pomocné koleso_2 -->
  <link name="balance_wheel_2_base">
    <visual>
      <geometry>
        <box size="0.02 0.02 0.02"/>
      </geometry>
      <material name="grey"/>
    </visual>
    <collision name="balance_wheel_2_base_collision">
      <geometry>
        <box size="0.02 0.02 0.02"/>
      </geometry>
    </collision>
    <inertial>
      <mass value="0.01"/>
      <origin xyz="0 0 0"/>
      <inertia ixx="0.0001" ixy="0" ixz="0" iyy="0.0001" iyz="0" izz="0.0001"/>
    </inertial>
  </link>
  <gazebo reference="balance_wheel_2_base">
    <material>Gazebo/Grey</material>
  </gazebo>
  <joint name="balance_wheel_2_base_joint" type="continuous">
    <parent link="base_link"/>
    <child link="balance_wheel_2_base"/>
    <origin xyz="-0.07 0 -0.034" rpy="0 0 0"/>
    <axis xyz="0 0 1"/>
    <dynamics damping="0.1" friction="0.01"/>
  </joint>
  
  <!-- Pomocné koleso_2 -->
  <link name="balance_wheel_2">
    <visual>
      <geometry>
        <sphere radius="0.009"/>
      </geometry>
      <material name="black"/>
    </visual>
    <collision name="balance_wheel_2_collision">
      <geometry>
        <sphere radius="0.009"/>
      </geometry>
    </collision>
    <inertial>
      <mass value="0.05"/>
      <origin xyz="0 0 0"/>
      <inertia ixx="0.0005" ixy="0" ixz="0" iyy="0.0005" iyz="0" izz="0.0005"/>
    </inertial>
  </link>
  <gazebo reference="balance_wheel_2">
    <material>Gazebo/Black</material>
    <mu1>0.1</mu1>
    <mu2>0.1</mu2>
  </gazebo>
  <joint name="balance_wheel_2_joint" type="fixed">
    <parent link="balance_wheel_2_base"/>
    <child link="balance_wheel_2"/>
    <origin xyz="0 0 -0.01" rpy="1.5707 0 0"/> <!-- Úprava origin -0.1 -->
  </joint>

  <!-- Anténka_1 -->
  <link name="antenna_1">
    <visual>
      <geometry>
        <cylinder radius="0.005" length="0.15"/>
      </geometry>
      <material name="black"/>
    </visual>
    <collision name="antenna_1_collision">
      <geometry>
        <cylinder radius="0.005" length="0.15"/>
      </geometry>
    </collision>
    <inertial>
      <mass value="0.02"/>
      <origin xyz="0 0 0"/>
      <inertia ixx="0.0002" ixy="0" ixz="0" iyy="0.0002" iyz="0" izz="0.0002"/>
    </inertial>
  </link>
  <gazebo reference="antenna_1">
    <material>Gazebo/Black</material>
  </gazebo>
  <joint name="antenna_1_joint" type="fixed">
    <parent link="base_link"/>
    <child link="antenna_1"/>
    <origin xyz="-0.08 0.04 0.09" rpy="0 0 0"/>
  </joint>

  <!-- Anténka_2 -->
  <link name="antenna_2">
    <visual>
      <geometry>
        <cylinder radius="0.005" length="0.15"/>
      </geometry>
      <material name="black"/>
    </visual>
    <collision name="antenna_2_collision">
      <geometry>
        <cylinder radius="0.005" length="0.15"/>
      </geometry>
    </collision>
    <inertial>
      <mass value="0.02"/>
      <origin xyz="0 0 0"/>
      <inertia ixx="0.0002" ixy="0" ixz="0" iyy="0.0002" iyz="0" izz="0.0002"/>
    </inertial>
  </link>
  <gazebo reference="antenna_2">
    <material>Gazebo/Black</material>
  </gazebo>
  <joint name="antenna_2_joint" type="fixed">
    <parent link="base_link"/>
    <child link="antenna_2"/>
    <origin xyz="-0.08 -0.04 0.09" rpy="0 0 0"/>
  </joint>

  <!-- Piliere spodné -->
  <link name="pillar_1">
    <visual>
      <geometry>
        <cylinder radius="0.005" length="0.05"/>
      </geometry>
      <material name="black"/>
    </visual>
    <collision name="pillar_1_collision">
      <geometry>
        <cylinder radius="0.005" length="0.05"/>
      </geometry>
    </collision>
    <inertial>
      <mass value="0.05"/>
      <origin xyz="0 0 0"/>
      <inertia ixx="0.0005" ixy="0" ixz="0" iyy="0.0005" iyz="0" izz="0.0005"/>
    </inertial>
  </link>
  <gazebo reference="pillar_1">
    <material>Gazebo/Black</material>
  </gazebo>
  <joint name="pillar_1_joint" type="fixed">
    <parent link="base_link"/>
    <child link="pillar_1"/>
    <origin xyz="0.05 0.05 0.025" rpy="0 0 0"/>
  </joint>

  <link name="pillar_2">
    <visual>
      <geometry>
        <cylinder radius="0.005" length="0.05"/>
      </geometry>
      <material name="black"/>
    </visual>
    <collision name="pillar_2_collision">
      <geometry>
        <cylinder radius="0.005" length="0.05"/>
      </geometry>
    </collision>
    <inertial>
      <mass value="0.05"/>
      <origin xyz="0 0 0"/>
      <inertia ixx="0.0005" ixy="0" ixz="0" iyy="0.0005" iyz="0" izz="0.0005"/>
    </inertial>
  </link>
  <gazebo reference="pillar_2">
    <material>Gazebo/Black</material>
  </gazebo>
  <joint name="pillar_2_joint" type="fixed">
    <parent link="base_link"/>
    <child link="pillar_2"/>
    <origin xyz="-0.05 0.05 0.025" rpy="0 0 0"/>
  </joint>

  <link name="pillar_3">
    <visual>
      <geometry>
        <cylinder radius="0.005" length="0.05"/>
      </geometry>
      <material name="black"/>
    </visual>
    <collision name="pillar_3_collision">
      <geometry>
        <cylinder radius="0.005" length="0.05"/>
      </geometry>
    </collision>
    <inertial>
      <mass value="0.05"/>
      <origin xyz="0 0 0"/>
      <inertia ixx="0.0005" ixy="0" ixz="0" iyy="0.0005" iyz="0" izz="0.0005"/>
    </inertial>
  </link>
  <gazebo reference="pillar_3">
    <material>Gazebo/Black</material>
  </gazebo>
  <joint name="pillar_3_joint" type="fixed">
    <parent link="base_link"/>
    <child link="pillar_3"/>
    <origin xyz="0.05 -0.05 0.025" rpy="0 0 0"/>
  </joint>

  <link name="pillar_4">
    <visual>
      <geometry>
        <cylinder radius="0.005" length="0.05"/>
      </geometry>
      <material name="black"/>
    </visual>
    <collision name="pillar_4_collision">
      <geometry>
        <cylinder radius="0.005" length="0.05"/>
      </geometry>
    </collision>
    <inertial>
      <mass value="0.05"/>
      <origin xyz="0 0 0"/>
      <inertia ixx="0.0005" ixy="0" ixz="0" iyy="0.0005" iyz="0" izz="0.0005"/>
    </inertial>
  </link>
  <gazebo reference="pillar_4">
    <material>Gazebo/Black</material>
  </gazebo>
  <joint name="pillar_4_joint" type="fixed">
    <parent link="base_link"/>
    <child link="pillar_4"/>
    <origin xyz="-0.05 -0.05 0.025" rpy="0 0 0"/>
  </joint>

  <!-- Speaker -->
  <link name="speaker">
    <visual>
      <geometry>
        <cylinder radius="0.01" length="0.004"/>
      </geometry>
      <material name="black"/>
    </visual>
    <collision name="speaker_collision">
      <geometry>
        <cylinder radius="0.01" length="0.004"/>
      </geometry>
    </collision>
    <inertial>
      <mass value="0.01"/>
      <origin xyz="0 0 0"/>
      <inertia ixx="0.0001" ixy="0" ixz="0" iyy="0.0001" iyz="0" izz="0.0001"/>
    </inertial>
  </link>
  <gazebo reference="speaker">
    <material>Gazebo/Black</material>
  </gazebo>
  <joint name="speaker_joint" type="fixed">
    <parent link="base_link"/>
    <child link="speaker"/>
    <origin xyz="-0.05 0.075 0.026" rpy="0 0 0"/>
  </joint>

  <!-- Podstavec -->
  <link name="plate">
    <visual>
      <geometry>
        <box size="0.12 0.12 0.001"/>
      </geometry>
      <material name="dark_green"/>
    </visual>
    <collision name="plate_collision">
      <geometry>
        <box size="0.12 0.12 0.001"/>
      </geometry>
    </collision>
    <inertial>
      <mass value="0.1"/>
      <origin xyz="0 0 0"/>
      <inertia ixx="0.001" ixy="0" ixz="0" iyy="0.001" iyz="0" izz="0.001"/>
    </inertial>
  </link>
  <gazebo reference="plate">
    <material>Gazebo/DarkGreen</material>
  </gazebo>
  <joint name="plate_joint" type="fixed">
    <parent link="base_link"/>
    <child link="plate"/>
    <origin xyz="0 0 0.050" rpy="0 0 0"/>
  </joint>

  <!-- Matičná doska -->
  <link name="motherboard">
    <visual>
      <geometry>
        <box size="0.08 0.08 0.009"/>
      </geometry>
      <material name="grey"/>
    </visual>
    <collision name="motherboard_collision">
      <geometry>
        <box size="0.08 0.08 0.009"/>
      </geometry>
    </collision>
    <inertial>
      <mass value="0.2"/>
      <origin xyz="0 0 0"/>
      <inertia ixx="0.001" ixy="0" ixz="0" iyy="0.001" iyz="0" izz="0.001"/>
    </inertial>
  </link>
  <gazebo reference="motherboard">
    <material>Gazebo/Grey</material>
  </gazebo>
  <joint name="motherboard_joint" type="fixed">
    <parent link="plate"/>
    <child link="motherboard"/>
    <origin xyz="0 0 0.005" rpy="0 0 0"/>
  </joint>

  <!-- Podstavec_2_vrchný -->
  <link name="top_plate">
    <visual>
      <geometry>
        <box size="0.12 0.12 0.005"/>
      </geometry>
      <material name="medium_green"/>
    </visual>
    <collision name="top_plate_collision">
      <geometry>
        <box size="0.12 0.12 0.005"/>
      </geometry>
    </collision>
    <inertial>
      <mass value="0.1"/>
      <origin xyz="0 0 0"/>
      <inertia ixx="0.0005" ixy="0" ixz="0" iyy="0.0005" iyz="0" izz="0.0005"/>
    </inertial>
  </link>
  <gazebo reference="top_plate">
    <material>Gazebo/Green</material>
  </gazebo>
  <joint name="top_plate_joint" type="fixed">
    <parent link="plate"/>
    <child link="top_plate"/>
    <origin xyz="0 0 0.025" rpy="0 0 0"/>
  </joint>

  <!-- Jetson Nano počítač -->
  <link name="jetson_nano">
    <visual>
      <geometry>
        <box size="0.08 0.08 0.014"/>
      </geometry>
      <material name="dark_grey"/>
    </visual>
    <collision name="jetson_nano_collision">
      <geometry>
        <box size="0.08 0.08 0.014"/>
      </geometry>
    </collision>
    <inertial>
      <mass value="0.2"/>
      <origin xyz="0 0 0"/>
      <inertia ixx="0.001" ixy="0" ixz="0" iyy="0.001" iyz="0" izz="0.001"/>
    </inertial>
  </link>
  <gazebo reference="jetson_nano">
    <material>Gazebo/DarkGrey</material>
  </gazebo>
  <joint name="jetson_nano_joint" type="fixed">
    <parent link="top_plate"/>
    <child link="jetson_nano"/>
    <origin xyz="0 0 -0.005" rpy="0 0 0"/>
  </joint>

  <!-- Piliere vrchné -->
  <link name="pillar_5">
    <visual>
      <geometry>
        <cylinder radius="0.005" length="0.025"/>
      </geometry>
      <material name="black"/>
    </visual>
    <collision name="pillar_5_collision">
      <geometry>
        <cylinder radius="0.005" length="0.025"/>
      </geometry>
    </collision>
    <inertial>
      <mass value="0.02"/>
      <origin xyz="0 0 0"/>
      <inertia ixx="0.0002" ixy="0" ixz="0" iyy="0.0002" iyz="0" izz="0.0002"/>
    </inertial>
  </link>
  <gazebo reference="pillar_5">
    <material>Gazebo/Black</material>
  </gazebo>
  <joint name="pillar_5_joint" type="fixed">
    <parent link="plate"/>
    <child link="pillar_5"/>
    <origin xyz="0.045 0.045 0.0125" rpy="0 0 0"/>
  </joint>

  <link name="pillar_6">
    <visual>
      <geometry>
        <cylinder radius="0.005" length="0.025"/>
      </geometry>
      <material name="black"/>
    </visual>
    <collision name="pillar_6_collision">
      <geometry>
        <cylinder radius="0.005" length="0.025"/>
      </geometry>
    </collision>
    <inertial>
      <mass value="0.02"/>
      <origin xyz="0 0 0"/>
      <inertia ixx="0.0002" ixy="0" ixz="0" iyy="0.0002" iyz="0" izz="0.0002"/>
    </inertial>
  </link>
  <gazebo reference="pillar_6">
    <material>Gazebo/Black</material>
  </gazebo>
  <joint name="pillar_6_joint" type="fixed">
    <parent link="plate"/>
    <child link="pillar_6"/>
    <origin xyz="-0.045 0.045 0.0125" rpy="0 0 0"/>
  </joint>

  <link name="pillar_7">
    <visual>
      <geometry>
        <cylinder radius="0.005" length="0.025"/>
      </geometry>
      <material name="black"/>
    </visual>
    <collision name="pillar_7_collision">
      <geometry>
        <cylinder radius="0.005" length="0.025"/>
      </geometry>
    </collision>
    <inertial>
      <mass value="0.02"/>
      <origin xyz="0 0 0"/>
      <inertia ixx="0.0002" ixy="0" ixz="0" iyy="0.0002" iyz="0" izz="0.0002"/>
    </inertial>
  </link>
  <gazebo reference="pillar_7">
    <material>Gazebo/Black</material>
  </gazebo>
  <joint name="pillar_7_joint" type="fixed">
    <parent link="plate"/>
    <child link="pillar_7"/>
    <origin xyz="0.045 -0.045 0.0125" rpy="0 0 0"/>
  </joint>

  <link name="pillar_8">
    <visual>
      <geometry>
        <cylinder radius="0.005" length="0.025"/>
      </geometry>
      <material name="black"/>
    </visual>
    <collision name="pillar_8_collision">
      <geometry>
        <cylinder radius="0.005" length="0.025"/>
      </geometry>
    </collision>
    <inertial>
      <mass value="0.02"/>
      <origin xyz="0 0 0"/>
      <inertia ixx="0.0002" ixy="0" ixz="0" iyy="0.0002" iyz="0" izz="0.0002"/>
    </inertial>
  </link>
  <gazebo reference="pillar_8">
    <material>Gazebo/Black</material>
  </gazebo>
  <joint name="pillar_8_joint" type="fixed">
    <parent link="plate"/>
    <child link="pillar_8"/>
    <origin xyz="-0.045 -0.045 0.0125" rpy="0 0 0"/>
  </joint>

  <!-- Batérie -->
  <link name="battery_1">
    <visual>
      <geometry>
        <cylinder radius="0.009" length="0.050"/>
      </geometry>
      <material name="yellow"/>
    </visual>
    <collision name="battery_1_collision">
      <geometry>
        <cylinder radius="0.009" length="0.050"/>
      </geometry>
    </collision>
    <inertial>
      <mass value="0.05"/>
      <origin xyz="0 0 0"/>
      <inertia ixx="0.0005" ixy="0" ixz="0" iyy="0.0005" iyz="0" izz="0.0005"/>
    </inertial>
  </link>
  <gazebo reference="battery_1">
    <material>Gazebo/Yellow</material>
  </gazebo>
  <joint name="battery_1_joint" type="fixed">
    <parent link="plate"/>
    <child link="battery_1"/>
    <origin xyz="-0.018 0 -0.010" rpy="1.5707 1.5707 0"/>
  </joint>

  <link name="battery_2">
    <visual>
      <geometry>
        <cylinder radius="0.009" length="0.050"/>
      </geometry>
      <material name="yellow"/>
    </visual>
    <collision name="battery_2_collision">
      <geometry>
        <cylinder radius="0.009" length="0.050"/>
      </geometry>
    </collision>
    <inertial>
      <mass value="0.05"/>
      <origin xyz="0 0 0"/>
      <inertia ixx="0.0005" ixy="0" ixz="0" iyy="0.0005" iyz="0" izz="0.0005"/>
    </inertial>
  </link>
  <gazebo reference="battery_2">
    <material>Gazebo/Yellow</material>
  </gazebo>
  <joint name="battery_2_joint" type="fixed">
    <parent link="plate"/>
    <child link="battery_2"/>
    <origin xyz="0 0 -0.010" rpy="1.5707 1.5707 0"/>
  </joint>

  <link name="battery_3">
    <visual>
      <geometry>
        <cylinder radius="0.009" length="0.050"/>
      </geometry>
      <material name="yellow"/>
    </visual>
    <collision name="battery_3_collision">
      <geometry>
        <cylinder radius="0.009" length="0.050"/>
      </geometry>
    </collision>
    <inertial>
      <mass value="0.05"/>
      <origin xyz="0 0 0"/>
      <inertia ixx="0.0005" ixy="0" ixz="0" iyy="0.0005" iyz="0" izz="0.0005"/>
    </inertial>
  </link>
  <gazebo reference="battery_3">
    <material>Gazebo/Yellow</material>
  </gazebo>
  <joint name="battery_3_joint" type="fixed">
    <parent link="plate"/>
    <child link="battery_3"/>
    <origin xyz="0.018 0 -0.010" rpy="1.5707 1.5707 0"/>
  </joint>

  <!-- Podstavec pre kameru -->
  <link name="camera_base">
    <visual>
      <geometry>
        <box size="0.015 0.010 0.04"/>
      </geometry>
      <material name="green"/>
    </visual>
    <collision name="camera_base_collision">
      <geometry>
        <box size="0.015 0.010 0.04"/>
      </geometry>
    </collision>
    <inertial>
      <mass value="0.05"/>
      <origin xyz="0 0 0"/>
      <inertia ixx="0.0005" ixy="0" ixz="0" iyy="0.0005" iyz="0" izz="0.0005"/>
    </inertial>
  </link>
  <gazebo reference="camera_base">
    <material>Gazebo/Green</material>
  </gazebo>
  <joint name="camera_base_joint" type="fixed">
    <parent link="base_link"/>
    <child link="camera_base"/>
    <origin xyz="0.09 0 0.045" rpy="0 0 0"/>
  </joint>

  <!-- Kamera -->
  <!-- <pose>0.10000000000000001 0 0.025 0 0 0</pose> upraveny pose pre .sdf -->
  <link name="camera">
    <visual>
      <geometry>
        <box size="0.02 0.02 0.02"/>
      </geometry>
      <material name="black"/>
    </visual>
    <collision name="camera_collision">
      <geometry>
        <box size="0.02 0.02 0.02"/>
      </geometry>
    </collision>
    <inertial>
      <mass value="0.05"/>
      <origin xyz="0 0 0"/>
      <inertia ixx="0.0001" ixy="0" ixz="0" iyy="0.0001" iyz="0" izz="0.0001"/>
    </inertial>
  </link>
  <gazebo reference="camera">
    <material>Gazebo/Black</material>
    <sensor type="camera" name="sim_camera">
      <update_rate>30</update_rate>
      <camera>
        <horizontal_fov>1.39626</horizontal_fov>
        <image>
          <width>640</width>
          <height>480</height>
          <format>R8G8B8</format>
        </image>
        <clip>
          <near>0.1</near>
          <far>100</far>
        </clip>
      </camera>
      <always_on>1</always_on>
      <visualize>true</visualize>
      <plugin name="gz::sim::systems::Camera" filename="gz-sim-camera-system">
        <topic>image</topic>
        <gz_frame_id>camera</gz_frame_id>
      </plugin>
    </sensor>
  </gazebo>

  <joint name="camera_joint" type="fixed">
    <parent link="camera_base"/>
    <child link="camera"/>
    <origin xyz="0.01 0 0.025" rpy="0 0.15 0"/> <!-- Upravený origin 0.03 -->
  </joint>

  <!-- Podstavec pre LIDAR -->
  <link name="lidar_base">
    <visual>
      <geometry>
        <cylinder radius="0.04" length="0.030"/>
      </geometry>
      <material name="green"/>
    </visual>
    <collision name="lidar_base_collision">
      <geometry>
        <cylinder radius="0.04" length="0.030"/>
      </geometry>
    </collision>
    <inertial>
      <mass value="0.1"/>
      <origin xyz="0 0 0"/>
      <inertia ixx="0.001" ixy="0" ixz="0" iyy="0.001" iyz="0" izz="0.002"/>
    </inertial>
  </link>
  <gazebo reference="lidar_base">
    <material>Gazebo/Green</material>
  </gazebo>

  <joint name="lidar_base_joint" type="fixed">
    <parent link="top_plate"/>
    <child link="lidar_base"/>
    <origin xyz="0 0 0.010" rpy="0 0 0"/>
  </joint>

  <!-- Lidar -->
  <link name="lidar">
    <visual>
      <geometry>
        <cylinder radius="0.04" length="0.02"/>
      </geometry>
      <material name="black"/>
    </visual>
    <collision name="lidar_collision">
      <geometry>
        <cylinder radius="0.04" length="0.02"/>
      </geometry>
    </collision>
    <inertial>
      <mass value="0.1"/>
      <origin xyz="0 0 0"/>
      <inertia ixx="0.001" ixy="0" ixz="0" iyy="0.001" iyz="0" izz="0.002"/>
    </inertial>
  </link>
  <gazebo reference="lidar">
    <material>Gazebo/Black</material>
    <sensor type="gpu_lidar" name="lidar_sensor">
      <update_rate>10</update_rate>
      <ray>
        <scan>
          <horizontal>
            <samples>640</samples>
            <resolution>1</resolution>
            <min_angle>-3.14</min_angle>
            <max_angle>3.14</max_angle>
          </horizontal>
          <vertical>
            <samples>1</samples>
            <resolution>0.01</resolution>
            <min_angle>0</min_angle>
            <max_angle>0</max_angle>
          </vertical>
        </scan>
        <range>
          <min>0.08</min>
          <max>10.0</max>
          <resolution>0.01</resolution>
        </range>
      </ray>
      <always_on>1</always_on>
      <visualize>true</visualize>
      <plugin name="gz::sim::systems::GpuLidar" filename="gz-sim-gpu-lidar-system">
        <topic>scan</topic>
        <gz_frame_id>lidar</gz_frame_id>
      </plugin>
    </sensor>
  </gazebo>

  <joint name="lidar_joint" type="fixed">
    <parent link="lidar_base"/>
    <child link="lidar"/>
    <origin xyz="0 0 0.025" rpy="0 0 0"/>
  </joint>
  
  <!-- Diferenciálny pohon -->
  <gazebo>
    <plugin name="gz::sim::systems::DiffDrive" filename="gz-sim-diff-drive-system">
      <left_joint>left_wheel_joint</left_joint>
      <right_joint>right_wheel_joint</right_joint>
      <wheel_separation>0.21325</wheel_separation>
      <wheel_radius>0.033</wheel_radius>
      <odom_topic>odom</odom_topic>
      <odom_publish_frequency>50</odom_publish_frequency>
      <topic>cmd_vel</topic>
      <cmd_timeout>0.5</cmd_timeout>
      <tf_topic>tf</tf_topic>
      <frame_id>odom</frame_id>
      <child_frame_id>base_link</child_frame_id>
      <publish_tf>true</publish_tf>
    </plugin>
  </gazebo>

  <!-- JointStatePublisher plugin -->
  <gazebo>
    <plugin name="gz::sim::systems::JointStatePublisher" filename="gz-sim-joint-state-publisher-system">
      <topic>joint_states</topic>
      <joint_name>left_wheel_joint</joint_name>
      <joint_name>right_wheel_joint</joint_name>
      <joint_name>balance_wheel_base_joint</joint_name>
      <joint_name>balance_wheel_2_base_joint</joint_name>
    </plugin>
  </gazebo>

</robot>
